{"name": "test_data_driven_testing[test300@mailinator.com-test@143-Valid]", "status": "failed", "statusDetails": {"message": "AssertionError: assert False", "trace": "self = <test_004_DDT.Test_Data_Driven object at 0x0000029E4F5F19A0>\nsetup = <selenium.webdriver.chrome.webdriver.WebDriver (session=\"872eea77243007607921853836e70761\")>, username = 'test300@mailinator.com'\npassword = 'test@143', expected_result = 'Valid'\n\n    @pytest.mark.parametrize(\"username, password, expected_result\", get_exceldata(path, \"Sheet1\"))\n    def test_data_driven_testing(self, setup, username, password, expected_result):\n        self.logger.info(\"**** Setting up the browser ****\")\n    \n        self.driver = setup\n        self.driver.maximize_window()\n    \n        try:\n            # Navigate to Login Page\n            self.driver.get(self.baseurl)\n            self.hp = Homepage(self.driver)\n            self.hp.clickmyaccount()\n            self.hp.clicklogin()\n            self.ma = My_Account_page(self.driver)\n    \n        except Exception as e:\n            self.logger.error(f\"Error during navigation: {e}\")\n            allure.attach(self.driver.get_screenshot_as_png(), name=\"Error_Login_Page\", attachment_type=AttachmentType.PNG)\n            self.driver.quit()\n            assert False\n    \n        try:\n            # Perform Login\n            self.lp = Login(self.driver)\n            self.lp.click_email(username)\n            self.lp.click_password(password)\n            self.lp.click_login()\n    \n        except Exception as e:\n            self.logger.error(f\"Error during login execution: {e}\")\n            allure.attach(self.driver.get_screenshot_as_png(), name=\"Login_Execution_Error\", attachment_type=AttachmentType.PNG)\n            self.driver.quit()\n            assert False\n    \n        try:\n            # Initialize actual_result to avoid AttributeError\n            self.actual_result = self.lp.myaccount_page()\n    \n            if self.actual_result == expected_result:\n                self.logger.info(\n                    f\"Test Passed for {username}: Expected = {expected_result}, Got = {self.actual_result}\")\n                assert True\n            else:\n                self.logger.error(\n                    f\"Test Failed for {username}: Expected = {expected_result}, Got = {self.actual_result}\")\n                allure.attach(self.driver.get_screenshot_as_png(), name=\"Test_Failure\",\n                              attachment_type=AttachmentType.PNG)\n>               assert False\nE               assert False\n\ntestCases\\Data Driven Test\\test_004_DDT.py:68: AssertionError\n\nDuring handling of the above exception, another exception occurred:\n\nself = <test_004_DDT.Test_Data_Driven object at 0x0000029E4F5F19A0>\nsetup = <selenium.webdriver.chrome.webdriver.WebDriver (session=\"872eea77243007607921853836e70761\")>, username = 'test300@mailinator.com'\npassword = 'test@143', expected_result = 'Valid'\n\n    @pytest.mark.parametrize(\"username, password, expected_result\", get_exceldata(path, \"Sheet1\"))\n    def test_data_driven_testing(self, setup, username, password, expected_result):\n        self.logger.info(\"**** Setting up the browser ****\")\n    \n        self.driver = setup\n        self.driver.maximize_window()\n    \n        try:\n            # Navigate to Login Page\n            self.driver.get(self.baseurl)\n            self.hp = Homepage(self.driver)\n            self.hp.clickmyaccount()\n            self.hp.clicklogin()\n            self.ma = My_Account_page(self.driver)\n    \n        except Exception as e:\n            self.logger.error(f\"Error during navigation: {e}\")\n            allure.attach(self.driver.get_screenshot_as_png(), name=\"Error_Login_Page\", attachment_type=AttachmentType.PNG)\n            self.driver.quit()\n            assert False\n    \n        try:\n            # Perform Login\n            self.lp = Login(self.driver)\n            self.lp.click_email(username)\n            self.lp.click_password(password)\n            self.lp.click_login()\n    \n        except Exception as e:\n            self.logger.error(f\"Error during login execution: {e}\")\n            allure.attach(self.driver.get_screenshot_as_png(), name=\"Login_Execution_Error\", attachment_type=AttachmentType.PNG)\n            self.driver.quit()\n            assert False\n    \n        try:\n            # Initialize actual_result to avoid AttributeError\n            self.actual_result = self.lp.myaccount_page()\n    \n            if self.actual_result == expected_result:\n                self.logger.info(\n                    f\"Test Passed for {username}: Expected = {expected_result}, Got = {self.actual_result}\")\n                assert True\n            else:\n                self.logger.error(\n                    f\"Test Failed for {username}: Expected = {expected_result}, Got = {self.actual_result}\")\n                allure.attach(self.driver.get_screenshot_as_png(), name=\"Test_Failure\",\n                              attachment_type=AttachmentType.PNG)\n                assert False\n        except Exception as e:\n            self.logger.error(f\"Unexpected error during validation: {e}\")\n            allure.attach(self.driver.get_screenshot_as_png(), name=\"Unexpected_Error\",\n                          attachment_type=AttachmentType.PNG)\n>           assert False\nE           assert False\n\ntestCases\\Data Driven Test\\test_004_DDT.py:73: AssertionError"}, "attachments": [{"name": "Test_Failure", "source": "34d3206f-1567-409d-8c42-3d4cdd2105d1-attachment.png", "type": "image/png"}, {"name": "Unexpected_Error", "source": "112718e4-93d6-4c4a-b1cc-608035df48a8-attachment.png", "type": "image/png"}, {"name": "log", "source": "979dee04-b883-444b-a8f9-4e654bf58562-attachment.txt", "type": "text/plain"}], "parameters": [{"name": "username", "value": "'test300@mailinator.com'"}, {"name": "password", "value": "'test@143'"}, {"name": "expected_result", "value": "'Valid'"}], "start": 1740906923538, "stop": 1740906933081, "uuid": "34f68694-6487-499c-8eb1-e53c58352213", "historyId": "3f621fecf7541fd151a3a2d8badc9ac6", "testCaseId": "feaf2845cd517faac78063da184e07ae", "fullName": "testCases.Data Driven Test.test_004_DDT.Test_Data_Driven#test_data_driven_testing", "labels": [{"name": "parentSuite", "value": "testCases.Data Driven Test"}, {"name": "suite", "value": "test_004_DDT"}, {"name": "subSuite", "value": "Test_Data_Driven"}, {"name": "host", "value": "DESKTOP-DL1JSBI"}, {"name": "thread", "value": "4812-MainThread"}, {"name": "framework", "value": "pytest"}, {"name": "language", "value": "cpython3"}, {"name": "package", "value": "testCases.Data Driven Test.test_004_DDT"}]}