{"name": "test_data_driven_testing[test100@mailinator.com-1243-Invalid]", "status": "failed", "statusDetails": {"message": "AssertionError: assert False", "trace": "self = <test_004_DDT.Test_Data_Driven object at 0x000002B2C55F6850>\nsetup = <selenium.webdriver.chrome.webdriver.WebDriver (session=\"232ed325f82e652cae58536db8e2b897\")>\nusername = 'test100@mailinator.com', password = 1243\nexpected_result = 'Invalid'\n\n    @pytest.mark.parametrize(\"username, password, expected_result\", get_exceldata(path, \"Sheet1\"))\n    def test_data_driven_testing(self, setup, username, password, expected_result):\n        self.logger.info(\"**** Setting up the browser ****\")\n    \n        self.driver = setup\n        self.driver.maximize_window()\n    \n        try:\n            # Navigate to Login Page\n            self.driver.get(self.baseurl)\n            self.hp = Homepage(self.driver)\n            self.hp.clickmyaccount()\n            self.hp.clicklogin()\n            self.ma = My_Account_page(self.driver)\n    \n        except Exception as e:\n            self.logger.error(f\"Error during navigation: {e}\")\n            allure.attach(self.driver.get_screenshot_as_png(), name=\"Error_Login_Page\", attachment_type=AttachmentType.PNG)\n            self.driver.quit()\n            assert False\n    \n        try:\n            # Perform Login\n            self.lp = Login(self.driver)\n            self.lp.click_email(username)\n            self.lp.click_password(password)\n            self.lp.click_login()\n    \n        except Exception as e:\n            self.logger.error(f\"Error during login execution: {e}\")\n            allure.attach(self.driver.get_screenshot_as_png(), name=\"Login_Execution_Error\", attachment_type=AttachmentType.PNG)\n            self.driver.quit()\n            assert False\n    \n        try:\n            # Initialize actual_result to avoid AttributeError\n            self.actual_result = self.lp.myaccount_page()\n    \n            if self.actual_result == expected_result:\n                self.logger.info(\n                    f\"Test Passed for {username}: Expected = {expected_result}, Got = {self.actual_result}\")\n                assert True\n            else:\n                self.logger.error(\n                    f\"Test Failed for {username}: Expected = {expected_result}, Got = {self.actual_result}\")\n                allure.attach(self.driver.get_screenshot_as_png(), name=\"Test_Failure\",\n                              attachment_type=AttachmentType.PNG)\n>               assert False\nE               assert False\n\ntestCases\\Data Driven Test\\test_004_DDT.py:68: AssertionError\n\nDuring handling of the above exception, another exception occurred:\n\nself = <test_004_DDT.Test_Data_Driven object at 0x000002B2C55F6850>\nsetup = <selenium.webdriver.chrome.webdriver.WebDriver (session=\"232ed325f82e652cae58536db8e2b897\")>\nusername = 'test100@mailinator.com', password = 1243\nexpected_result = 'Invalid'\n\n    @pytest.mark.parametrize(\"username, password, expected_result\", get_exceldata(path, \"Sheet1\"))\n    def test_data_driven_testing(self, setup, username, password, expected_result):\n        self.logger.info(\"**** Setting up the browser ****\")\n    \n        self.driver = setup\n        self.driver.maximize_window()\n    \n        try:\n            # Navigate to Login Page\n            self.driver.get(self.baseurl)\n            self.hp = Homepage(self.driver)\n            self.hp.clickmyaccount()\n            self.hp.clicklogin()\n            self.ma = My_Account_page(self.driver)\n    \n        except Exception as e:\n            self.logger.error(f\"Error during navigation: {e}\")\n            allure.attach(self.driver.get_screenshot_as_png(), name=\"Error_Login_Page\", attachment_type=AttachmentType.PNG)\n            self.driver.quit()\n            assert False\n    \n        try:\n            # Perform Login\n            self.lp = Login(self.driver)\n            self.lp.click_email(username)\n            self.lp.click_password(password)\n            self.lp.click_login()\n    \n        except Exception as e:\n            self.logger.error(f\"Error during login execution: {e}\")\n            allure.attach(self.driver.get_screenshot_as_png(), name=\"Login_Execution_Error\", attachment_type=AttachmentType.PNG)\n            self.driver.quit()\n            assert False\n    \n        try:\n            # Initialize actual_result to avoid AttributeError\n            self.actual_result = self.lp.myaccount_page()\n    \n            if self.actual_result == expected_result:\n                self.logger.info(\n                    f\"Test Passed for {username}: Expected = {expected_result}, Got = {self.actual_result}\")\n                assert True\n            else:\n                self.logger.error(\n                    f\"Test Failed for {username}: Expected = {expected_result}, Got = {self.actual_result}\")\n                allure.attach(self.driver.get_screenshot_as_png(), name=\"Test_Failure\",\n                              attachment_type=AttachmentType.PNG)\n                assert False\n        except Exception as e:\n            self.logger.error(f\"Unexpected error during validation: {e}\")\n            allure.attach(self.driver.get_screenshot_as_png(), name=\"Unexpected_Error\",\n                          attachment_type=AttachmentType.PNG)\n>           assert False\nE           assert False\n\ntestCases\\Data Driven Test\\test_004_DDT.py:73: AssertionError"}, "attachments": [{"name": "Test_Failure", "source": "ca4ac433-56d4-4540-b23c-873796b6fd0d-attachment.png", "type": "image/png"}, {"name": "Unexpected_Error", "source": "00007e23-0cb2-41a7-b5da-1813fcac1be8-attachment.png", "type": "image/png"}, {"name": "log", "source": "3cec7334-67b7-45a3-9b0f-dcadb9c5d8b2-attachment.txt", "type": "text/plain"}], "parameters": [{"name": "username", "value": "'test100@mailinator.com'"}, {"name": "password", "value": "1243"}, {"name": "expected_result", "value": "'Invalid'"}], "start": 1740774479559, "stop": 1740774487424, "uuid": "8663f378-0b59-4334-a23c-2a7e9fb0d425", "historyId": "7120903687640f5717da33b756534f6f", "testCaseId": "feaf2845cd517faac78063da184e07ae", "fullName": "testCases.Data Driven Test.test_004_DDT.Test_Data_Driven#test_data_driven_testing", "labels": [{"name": "parentSuite", "value": "testCases.Data Driven Test"}, {"name": "suite", "value": "test_004_DDT"}, {"name": "subSuite", "value": "Test_Data_Driven"}, {"name": "host", "value": "DESKTOP-DL1JSBI"}, {"name": "thread", "value": "12188-MainThread"}, {"name": "framework", "value": "pytest"}, {"name": "language", "value": "cpython3"}, {"name": "package", "value": "testCases.Data Driven Test.test_004_DDT"}]}