{"name": "test_data_driven_testing[ndj@mailinator.com-a4iM2@qJaP7U4AS-Valid]", "status": "failed", "statusDetails": {"message": "AssertionError: assert False", "trace": "self = <test_004_DDT.Test_Data_Driven object at 0x0000029E4F706CC0>\nsetup = <selenium.webdriver.chrome.webdriver.WebDriver (session=\"407e94078e9c9217f9f48bedf293e179\")>, username = 'ndj@mailinator.com'\npassword = 'a4iM2@qJaP7U4AS', expected_result = 'Valid'\n\n    @pytest.mark.parametrize(\"username, password, expected_result\", get_exceldata(path, \"Sheet1\"))\n    def test_data_driven_testing(self, setup, username, password, expected_result):\n        self.logger.info(\"**** Setting up the browser ****\")\n    \n        self.driver = setup\n        self.driver.maximize_window()\n    \n        try:\n            # Navigate to Login Page\n            self.driver.get(self.baseurl)\n            self.hp = Homepage(self.driver)\n            self.hp.clickmyaccount()\n            self.hp.clicklogin()\n            self.ma = My_Account_page(self.driver)\n    \n        except Exception as e:\n            self.logger.error(f\"Error during navigation: {e}\")\n            allure.attach(self.driver.get_screenshot_as_png(), name=\"Error_Login_Page\", attachment_type=AttachmentType.PNG)\n            self.driver.quit()\n            assert False\n    \n        try:\n            # Perform Login\n            self.lp = Login(self.driver)\n            self.lp.click_email(username)\n            self.lp.click_password(password)\n            self.lp.click_login()\n    \n        except Exception as e:\n            self.logger.error(f\"Error during login execution: {e}\")\n            allure.attach(self.driver.get_screenshot_as_png(), name=\"Login_Execution_Error\", attachment_type=AttachmentType.PNG)\n            self.driver.quit()\n            assert False\n    \n        try:\n            # Initialize actual_result to avoid AttributeError\n            self.actual_result = self.lp.myaccount_page()\n    \n            if self.actual_result == expected_result:\n                self.logger.info(\n                    f\"Test Passed for {username}: Expected = {expected_result}, Got = {self.actual_result}\")\n                assert True\n            else:\n                self.logger.error(\n                    f\"Test Failed for {username}: Expected = {expected_result}, Got = {self.actual_result}\")\n                allure.attach(self.driver.get_screenshot_as_png(), name=\"Test_Failure\",\n                              attachment_type=AttachmentType.PNG)\n>               assert False\nE               assert False\n\ntestCases\\Data Driven Test\\test_004_DDT.py:68: AssertionError\n\nDuring handling of the above exception, another exception occurred:\n\nself = <test_004_DDT.Test_Data_Driven object at 0x0000029E4F706CC0>\nsetup = <selenium.webdriver.chrome.webdriver.WebDriver (session=\"407e94078e9c9217f9f48bedf293e179\")>, username = 'ndj@mailinator.com'\npassword = 'a4iM2@qJaP7U4AS', expected_result = 'Valid'\n\n    @pytest.mark.parametrize(\"username, password, expected_result\", get_exceldata(path, \"Sheet1\"))\n    def test_data_driven_testing(self, setup, username, password, expected_result):\n        self.logger.info(\"**** Setting up the browser ****\")\n    \n        self.driver = setup\n        self.driver.maximize_window()\n    \n        try:\n            # Navigate to Login Page\n            self.driver.get(self.baseurl)\n            self.hp = Homepage(self.driver)\n            self.hp.clickmyaccount()\n            self.hp.clicklogin()\n            self.ma = My_Account_page(self.driver)\n    \n        except Exception as e:\n            self.logger.error(f\"Error during navigation: {e}\")\n            allure.attach(self.driver.get_screenshot_as_png(), name=\"Error_Login_Page\", attachment_type=AttachmentType.PNG)\n            self.driver.quit()\n            assert False\n    \n        try:\n            # Perform Login\n            self.lp = Login(self.driver)\n            self.lp.click_email(username)\n            self.lp.click_password(password)\n            self.lp.click_login()\n    \n        except Exception as e:\n            self.logger.error(f\"Error during login execution: {e}\")\n            allure.attach(self.driver.get_screenshot_as_png(), name=\"Login_Execution_Error\", attachment_type=AttachmentType.PNG)\n            self.driver.quit()\n            assert False\n    \n        try:\n            # Initialize actual_result to avoid AttributeError\n            self.actual_result = self.lp.myaccount_page()\n    \n            if self.actual_result == expected_result:\n                self.logger.info(\n                    f\"Test Passed for {username}: Expected = {expected_result}, Got = {self.actual_result}\")\n                assert True\n            else:\n                self.logger.error(\n                    f\"Test Failed for {username}: Expected = {expected_result}, Got = {self.actual_result}\")\n                allure.attach(self.driver.get_screenshot_as_png(), name=\"Test_Failure\",\n                              attachment_type=AttachmentType.PNG)\n                assert False\n        except Exception as e:\n            self.logger.error(f\"Unexpected error during validation: {e}\")\n            allure.attach(self.driver.get_screenshot_as_png(), name=\"Unexpected_Error\",\n                          attachment_type=AttachmentType.PNG)\n>           assert False\nE           assert False\n\ntestCases\\Data Driven Test\\test_004_DDT.py:73: AssertionError"}, "attachments": [{"name": "Test_Failure", "source": "be9dbb0d-b6fc-4d35-af57-db5b19a07905-attachment.png", "type": "image/png"}, {"name": "Unexpected_Error", "source": "1734c8e6-cf8e-4f25-9136-507da001c502-attachment.png", "type": "image/png"}, {"name": "log", "source": "8583f049-43e2-456f-a587-468b7fe7251d-attachment.txt", "type": "text/plain"}], "parameters": [{"name": "username", "value": "'ndj@mailinator.com'"}, {"name": "password", "value": "'a4iM2@qJaP7U4AS'"}, {"name": "expected_result", "value": "'Valid'"}], "start": 1740906885595, "stop": 1740906895549, "uuid": "30a76538-a4d8-463b-8e0e-a4b149315174", "historyId": "5824f2dfec43c90d8f7bae3ad7be7a74", "testCaseId": "feaf2845cd517faac78063da184e07ae", "fullName": "testCases.Data Driven Test.test_004_DDT.Test_Data_Driven#test_data_driven_testing", "labels": [{"name": "parentSuite", "value": "testCases.Data Driven Test"}, {"name": "suite", "value": "test_004_DDT"}, {"name": "subSuite", "value": "Test_Data_Driven"}, {"name": "host", "value": "DESKTOP-DL1JSBI"}, {"name": "thread", "value": "4812-MainThread"}, {"name": "framework", "value": "pytest"}, {"name": "language", "value": "cpython3"}, {"name": "package", "value": "testCases.Data Driven Test.test_004_DDT"}]}