{"name": "test_data_driven_testing[test200@mailinator.com-test@143-Valid]", "status": "failed", "statusDetails": {"message": "AssertionError: assert False", "trace": "self = <test_004_DDT.Test_Data_Driven object at 0x0000029E4F704A10>\nsetup = <selenium.webdriver.chrome.webdriver.WebDriver (session=\"6eccff35212b34273fe19a7f87cb6066\")>, username = 'test200@mailinator.com'\npassword = 'test@143', expected_result = 'Valid'\n\n    @pytest.mark.parametrize(\"username, password, expected_result\", get_exceldata(path, \"Sheet1\"))\n    def test_data_driven_testing(self, setup, username, password, expected_result):\n        self.logger.info(\"**** Setting up the browser ****\")\n    \n        self.driver = setup\n        self.driver.maximize_window()\n    \n        try:\n            # Navigate to Login Page\n            self.driver.get(self.baseurl)\n            self.hp = Homepage(self.driver)\n            self.hp.clickmyaccount()\n            self.hp.clicklogin()\n            self.ma = My_Account_page(self.driver)\n    \n        except Exception as e:\n            self.logger.error(f\"Error during navigation: {e}\")\n            allure.attach(self.driver.get_screenshot_as_png(), name=\"Error_Login_Page\", attachment_type=AttachmentType.PNG)\n            self.driver.quit()\n            assert False\n    \n        try:\n            # Perform Login\n            self.lp = Login(self.driver)\n            self.lp.click_email(username)\n            self.lp.click_password(password)\n            self.lp.click_login()\n    \n        except Exception as e:\n            self.logger.error(f\"Error during login execution: {e}\")\n            allure.attach(self.driver.get_screenshot_as_png(), name=\"Login_Execution_Error\", attachment_type=AttachmentType.PNG)\n            self.driver.quit()\n            assert False\n    \n        try:\n            # Initialize actual_result to avoid AttributeError\n            self.actual_result = self.lp.myaccount_page()\n    \n            if self.actual_result == expected_result:\n                self.logger.info(\n                    f\"Test Passed for {username}: Expected = {expected_result}, Got = {self.actual_result}\")\n                assert True\n            else:\n                self.logger.error(\n                    f\"Test Failed for {username}: Expected = {expected_result}, Got = {self.actual_result}\")\n                allure.attach(self.driver.get_screenshot_as_png(), name=\"Test_Failure\",\n                              attachment_type=AttachmentType.PNG)\n>               assert False\nE               assert False\n\ntestCases\\Data Driven Test\\test_004_DDT.py:68: AssertionError\n\nDuring handling of the above exception, another exception occurred:\n\nself = <test_004_DDT.Test_Data_Driven object at 0x0000029E4F704A10>\nsetup = <selenium.webdriver.chrome.webdriver.WebDriver (session=\"6eccff35212b34273fe19a7f87cb6066\")>, username = 'test200@mailinator.com'\npassword = 'test@143', expected_result = 'Valid'\n\n    @pytest.mark.parametrize(\"username, password, expected_result\", get_exceldata(path, \"Sheet1\"))\n    def test_data_driven_testing(self, setup, username, password, expected_result):\n        self.logger.info(\"**** Setting up the browser ****\")\n    \n        self.driver = setup\n        self.driver.maximize_window()\n    \n        try:\n            # Navigate to Login Page\n            self.driver.get(self.baseurl)\n            self.hp = Homepage(self.driver)\n            self.hp.clickmyaccount()\n            self.hp.clicklogin()\n            self.ma = My_Account_page(self.driver)\n    \n        except Exception as e:\n            self.logger.error(f\"Error during navigation: {e}\")\n            allure.attach(self.driver.get_screenshot_as_png(), name=\"Error_Login_Page\", attachment_type=AttachmentType.PNG)\n            self.driver.quit()\n            assert False\n    \n        try:\n            # Perform Login\n            self.lp = Login(self.driver)\n            self.lp.click_email(username)\n            self.lp.click_password(password)\n            self.lp.click_login()\n    \n        except Exception as e:\n            self.logger.error(f\"Error during login execution: {e}\")\n            allure.attach(self.driver.get_screenshot_as_png(), name=\"Login_Execution_Error\", attachment_type=AttachmentType.PNG)\n            self.driver.quit()\n            assert False\n    \n        try:\n            # Initialize actual_result to avoid AttributeError\n            self.actual_result = self.lp.myaccount_page()\n    \n            if self.actual_result == expected_result:\n                self.logger.info(\n                    f\"Test Passed for {username}: Expected = {expected_result}, Got = {self.actual_result}\")\n                assert True\n            else:\n                self.logger.error(\n                    f\"Test Failed for {username}: Expected = {expected_result}, Got = {self.actual_result}\")\n                allure.attach(self.driver.get_screenshot_as_png(), name=\"Test_Failure\",\n                              attachment_type=AttachmentType.PNG)\n                assert False\n        except Exception as e:\n            self.logger.error(f\"Unexpected error during validation: {e}\")\n            allure.attach(self.driver.get_screenshot_as_png(), name=\"Unexpected_Error\",\n                          attachment_type=AttachmentType.PNG)\n>           assert False\nE           assert False\n\ntestCases\\Data Driven Test\\test_004_DDT.py:73: AssertionError"}, "attachments": [{"name": "Test_Failure", "source": "dfa5f9c6-0c20-4417-a6eb-cd68cfab2d5c-attachment.png", "type": "image/png"}, {"name": "Unexpected_Error", "source": "6c4a26a3-1090-4cb6-b1f4-d4fdb4a3c3d1-attachment.png", "type": "image/png"}, {"name": "log", "source": "e949b81a-a98e-4141-9e63-38054e1c360b-attachment.txt", "type": "text/plain"}], "parameters": [{"name": "username", "value": "'test200@mailinator.com'"}, {"name": "password", "value": "'test@143'"}, {"name": "expected_result", "value": "'Valid'"}], "start": 1740906909432, "stop": 1740906918328, "uuid": "ccf4cc9c-e03a-4928-9ea8-78f4d5d907b1", "historyId": "4c0713b11890e5585cee9c6b1b01a0db", "testCaseId": "feaf2845cd517faac78063da184e07ae", "fullName": "testCases.Data Driven Test.test_004_DDT.Test_Data_Driven#test_data_driven_testing", "labels": [{"name": "parentSuite", "value": "testCases.Data Driven Test"}, {"name": "suite", "value": "test_004_DDT"}, {"name": "subSuite", "value": "Test_Data_Driven"}, {"name": "host", "value": "DESKTOP-DL1JSBI"}, {"name": "thread", "value": "4812-MainThread"}, {"name": "framework", "value": "pytest"}, {"name": "language", "value": "cpython3"}, {"name": "package", "value": "testCases.Data Driven Test.test_004_DDT"}]}