{"name": "test_data_driven_testing[test200@mailinator.com-test@143-Valid]", "status": "failed", "statusDetails": {"message": "AssertionError: assert False", "trace": "self = <test_004_DDT.Test_Data_Driven object at 0x000001D617541A30>\nsetup = <selenium.webdriver.chrome.webdriver.WebDriver (session=\"5c306d2dc67aeafbbe8fcc0edbbe8715\")>, username = 'test200@mailinator.com'\npassword = 'test@143', expected_result = 'Valid'\n\n    @pytest.mark.parametrize(\"username, password, expected_result\", get_exceldata(path, \"Sheet1\"))\n    def test_data_driven_testing(self, setup, username, password, expected_result):\n        self.logger.info(\"**** Setting up the browser ****\")\n    \n        self.driver = setup\n        self.driver.maximize_window()\n    \n        try:\n            # Navigate to Login Page\n            self.driver.get(self.baseurl)\n            self.hp = Homepage(self.driver)\n            self.hp.clickmyaccount()\n            self.hp.clicklogin()\n            self.ma = My_Account_page(self.driver)\n    \n            # Perform Login\n            self.lp = Login(self.driver)\n            self.lp.click_email(username)\n            self.lp.click_password(password)\n            self.lp.click_login()\n    \n            # Initialize actual_result to avoid AttributeError\n            self.actual_result = self.lp.myaccount_page()\n            self.result = self.actual_result.strip().lower()\n    \n            if self.result == expected_result:\n                self.logger.info(\n                    f\"Test Passed for {username}: Expected = {expected_result}, Got = {self.actual_result}\")\n                assert True\n            else:\n                self.logger.error(\n                    f\"Test Failed for {username}: Expected = {expected_result}, Got = {self.actual_result}\")\n                allure.attach(self.driver.get_screenshot_as_png(), name=\"Test_Failure\",\n                              attachment_type=AttachmentType.PNG)\n>               assert False\nE               assert False\n\ntestCases\\Data Driven Test\\test_004_DDT.py:55: AssertionError\n\nDuring handling of the above exception, another exception occurred:\n\nself = <test_004_DDT.Test_Data_Driven object at 0x000001D617541A30>\nsetup = <selenium.webdriver.chrome.webdriver.WebDriver (session=\"5c306d2dc67aeafbbe8fcc0edbbe8715\")>, username = 'test200@mailinator.com'\npassword = 'test@143', expected_result = 'Valid'\n\n    @pytest.mark.parametrize(\"username, password, expected_result\", get_exceldata(path, \"Sheet1\"))\n    def test_data_driven_testing(self, setup, username, password, expected_result):\n        self.logger.info(\"**** Setting up the browser ****\")\n    \n        self.driver = setup\n        self.driver.maximize_window()\n    \n        try:\n            # Navigate to Login Page\n            self.driver.get(self.baseurl)\n            self.hp = Homepage(self.driver)\n            self.hp.clickmyaccount()\n            self.hp.clicklogin()\n            self.ma = My_Account_page(self.driver)\n    \n            # Perform Login\n            self.lp = Login(self.driver)\n            self.lp.click_email(username)\n            self.lp.click_password(password)\n            self.lp.click_login()\n    \n            # Initialize actual_result to avoid AttributeError\n            self.actual_result = self.lp.myaccount_page()\n            self.result = self.actual_result.strip().lower()\n    \n            if self.result == expected_result:\n                self.logger.info(\n                    f\"Test Passed for {username}: Expected = {expected_result}, Got = {self.actual_result}\")\n                assert True\n            else:\n                self.logger.error(\n                    f\"Test Failed for {username}: Expected = {expected_result}, Got = {self.actual_result}\")\n                allure.attach(self.driver.get_screenshot_as_png(), name=\"Test_Failure\",\n                              attachment_type=AttachmentType.PNG)\n                assert False\n        except Exception as e:\n            self.logger.error(f\"Unexpected error during validation: {e}\")\n            allure.attach(self.driver.get_screenshot_as_png(), name=\"Unexpected_Error\",\n                          attachment_type=AttachmentType.PNG)\n>           assert False\nE           assert False\n\ntestCases\\Data Driven Test\\test_004_DDT.py:60: AssertionError"}, "attachments": [{"name": "Test_Failure", "source": "41c36c7e-3ac2-4460-8266-9411985db0e6-attachment.png", "type": "image/png"}, {"name": "Unexpected_Error", "source": "352ab1bf-21b9-4029-88e8-d89c3d63ab97-attachment.png", "type": "image/png"}, {"name": "log", "source": "6aef4a19-7187-4fe8-9d61-2a4c9fdb9c26-attachment.txt", "type": "text/plain"}], "parameters": [{"name": "username", "value": "'test200@mailinator.com'"}, {"name": "password", "value": "'test@143'"}, {"name": "expected_result", "value": "'Valid'"}], "start": 1740907614143, "stop": 1740907622789, "uuid": "e42f3bc2-0772-462a-8240-a08af0378721", "historyId": "4c0713b11890e5585cee9c6b1b01a0db", "testCaseId": "feaf2845cd517faac78063da184e07ae", "fullName": "testCases.Data Driven Test.test_004_DDT.Test_Data_Driven#test_data_driven_testing", "labels": [{"name": "parentSuite", "value": "testCases.Data Driven Test"}, {"name": "suite", "value": "test_004_DDT"}, {"name": "subSuite", "value": "Test_Data_Driven"}, {"name": "host", "value": "DESKTOP-DL1JSBI"}, {"name": "thread", "value": "4448-MainThread"}, {"name": "framework", "value": "pytest"}, {"name": "language", "value": "cpython3"}, {"name": "package", "value": "testCases.Data Driven Test.test_004_DDT"}]}