{"name": "test_data_driven_testing[test100@mailinator.com-1243-Invalid]", "status": "failed", "statusDetails": {"message": "AssertionError: assert False", "trace": "self = <test_004_DDT.Test_Data_Driven object at 0x000001D617542780>\nsetup = <selenium.webdriver.chrome.webdriver.WebDriver (session=\"5916d1c511a25eb09a75238c99773c3c\")>, username = 'test100@mailinator.com'\npassword = 1243, expected_result = 'Invalid'\n\n    @pytest.mark.parametrize(\"username, password, expected_result\", get_exceldata(path, \"Sheet1\"))\n    def test_data_driven_testing(self, setup, username, password, expected_result):\n        self.logger.info(\"**** Setting up the browser ****\")\n    \n        self.driver = setup\n        self.driver.maximize_window()\n    \n        try:\n            # Navigate to Login Page\n            self.driver.get(self.baseurl)\n            self.hp = Homepage(self.driver)\n            self.hp.clickmyaccount()\n            self.hp.clicklogin()\n            self.ma = My_Account_page(self.driver)\n    \n            # Perform Login\n            self.lp = Login(self.driver)\n            self.lp.click_email(username)\n            self.lp.click_password(password)\n            self.lp.click_login()\n    \n            # Initialize actual_result to avoid AttributeError\n            self.actual_result = self.lp.myaccount_page()\n            self.result = self.actual_result.strip().lower()\n    \n            if self.result == expected_result:\n                self.logger.info(\n                    f\"Test Passed for {username}: Expected = {expected_result}, Got = {self.actual_result}\")\n                assert True\n            else:\n                self.logger.error(\n                    f\"Test Failed for {username}: Expected = {expected_result}, Got = {self.actual_result}\")\n                allure.attach(self.driver.get_screenshot_as_png(), name=\"Test_Failure\",\n                              attachment_type=AttachmentType.PNG)\n>               assert False\nE               assert False\n\ntestCases\\Data Driven Test\\test_004_DDT.py:55: AssertionError\n\nDuring handling of the above exception, another exception occurred:\n\nself = <test_004_DDT.Test_Data_Driven object at 0x000001D617542780>\nsetup = <selenium.webdriver.chrome.webdriver.WebDriver (session=\"5916d1c511a25eb09a75238c99773c3c\")>, username = 'test100@mailinator.com'\npassword = 1243, expected_result = 'Invalid'\n\n    @pytest.mark.parametrize(\"username, password, expected_result\", get_exceldata(path, \"Sheet1\"))\n    def test_data_driven_testing(self, setup, username, password, expected_result):\n        self.logger.info(\"**** Setting up the browser ****\")\n    \n        self.driver = setup\n        self.driver.maximize_window()\n    \n        try:\n            # Navigate to Login Page\n            self.driver.get(self.baseurl)\n            self.hp = Homepage(self.driver)\n            self.hp.clickmyaccount()\n            self.hp.clicklogin()\n            self.ma = My_Account_page(self.driver)\n    \n            # Perform Login\n            self.lp = Login(self.driver)\n            self.lp.click_email(username)\n            self.lp.click_password(password)\n            self.lp.click_login()\n    \n            # Initialize actual_result to avoid AttributeError\n            self.actual_result = self.lp.myaccount_page()\n            self.result = self.actual_result.strip().lower()\n    \n            if self.result == expected_result:\n                self.logger.info(\n                    f\"Test Passed for {username}: Expected = {expected_result}, Got = {self.actual_result}\")\n                assert True\n            else:\n                self.logger.error(\n                    f\"Test Failed for {username}: Expected = {expected_result}, Got = {self.actual_result}\")\n                allure.attach(self.driver.get_screenshot_as_png(), name=\"Test_Failure\",\n                              attachment_type=AttachmentType.PNG)\n                assert False\n        except Exception as e:\n            self.logger.error(f\"Unexpected error during validation: {e}\")\n            allure.attach(self.driver.get_screenshot_as_png(), name=\"Unexpected_Error\",\n                          attachment_type=AttachmentType.PNG)\n>           assert False\nE           assert False\n\ntestCases\\Data Driven Test\\test_004_DDT.py:60: AssertionError"}, "attachments": [{"name": "Test_Failure", "source": "719c9a59-42ca-4777-8ab3-9692bfab037a-attachment.png", "type": "image/png"}, {"name": "Unexpected_Error", "source": "9a043b51-fded-4889-85e2-5887eab8cf90-attachment.png", "type": "image/png"}, {"name": "log", "source": "a84c27be-fcf1-406f-9692-d203df20145d-attachment.txt", "type": "text/plain"}], "parameters": [{"name": "username", "value": "'test100@mailinator.com'"}, {"name": "password", "value": "1243"}, {"name": "expected_result", "value": "'Invalid'"}], "start": 1740907600798, "stop": 1740907609646, "uuid": "3d27e380-1c4d-4894-9fb3-87fa76d40b56", "historyId": "7120903687640f5717da33b756534f6f", "testCaseId": "feaf2845cd517faac78063da184e07ae", "fullName": "testCases.Data Driven Test.test_004_DDT.Test_Data_Driven#test_data_driven_testing", "labels": [{"name": "parentSuite", "value": "testCases.Data Driven Test"}, {"name": "suite", "value": "test_004_DDT"}, {"name": "subSuite", "value": "Test_Data_Driven"}, {"name": "host", "value": "DESKTOP-DL1JSBI"}, {"name": "thread", "value": "4448-MainThread"}, {"name": "framework", "value": "pytest"}, {"name": "language", "value": "cpython3"}, {"name": "package", "value": "testCases.Data Driven Test.test_004_DDT"}]}